Workbook

Sheet Details
A1: Scenario details: | B1: Period of time | C1: Implications
A2: Power outage in LA | B2: Days 0 to 3 | C2: Terminals in LA dont operate. Refineries in LA dont operate
A3: Refineries shutdown | B3: Days 0 to 14 | C3: 14-Day Minimum Shutdown: The power outage forces a hard shutdown of all seven Los Angeles area refineries. This relies on that to restart operations, the ifnraestructure must follow strict protocols of reactivation + cleaning
A4: Refineries shutdown | B4: Days 0 to 28 | C4: Wilmington shuts down for 28 day
A5: Crude oil pipelines shut down | B5: Days 0 to 21 | C5: 25% of refineries crude oil filling capacity is shut down for 21 days.
A6: Pipeline segment LA-Colton | B6: Days 0 to 21 | C6: Shut down
A7: Pipeline segment Colton-Barstow | B7: Days 0 to 42 | C7: Shut down
A8: Pipeline segment Colton-Imperial | B8: Days 0 to 88 | C8: Shut down

Sheet supply
A1: supply_type | B1: name | C1: capacity_bbl_day
A2: refinery | B2: El Segundo | C2: 228000
A3: refinery | B3: Wilmington | C3: 110960
A4: refinery | B4: Carson | C4: 292000
A5: refinery | B5: Torrance | C5: 128000
A6: refinery | B6: Wilmington | C6: 68000
A7: refinery | B7: Wilmington | C7: 3150
A8: port | B8: Los Angeles | C8: 28236
A9: port | B9: Long Beach | C9: 9721

Sheet supply_disruption_scenario
A1: supply_type | B1: day | C1: percentage_of_capacity
A2: refinery | B2: 1 | C2: 0
A3: refinery | B3: =B2+1 -> 2 | C3: 0
A4: refinery | B4: =B3+1 -> 3 | C4: 0
A5: refinery | B5: =B4+1 -> 4 | C5: 0
A6: refinery | B6: =B5+1 -> 5 | C6: 0
A7: refinery | B7: =B6+1 -> 6 | C7: 0
A8: refinery | B8: =B7+1 -> 7 | C8: 0
A9: refinery | B9: =B8+1 -> 8 | C9: 0
A10: refinery | B10: =B9+1 -> 9 | C10: 0
A11: refinery | B11: =B10+1 -> 10 | C11: 0
A12: refinery | B12: =B11+1 -> 11 | C12: 0
A13: refinery | B13: =B12+1 -> 12 | C13: 0
A14: refinery | B14: =B13+1 -> 13 | C14: 0
A15: refinery | B15: =B14+1 -> 14 | C15: 0
A16: refinery | B16: =B15+1 -> 15 | C16: =1-0.45 -> 0.55
A17: refinery | B17: =B16+1 -> 16 | C17: =1-0.45 -> 0.55
A18: refinery | B18: =B17+1 -> 17 | C18: =1-0.45 -> 0.55
A19: refinery | B19: =B18+1 -> 18 | C19: =1-0.45 -> 0.55
A20: refinery | B20: =B19+1 -> 19 | C20: =1-0.45 -> 0.55
A21: refinery | B21: =B20+1 -> 20 | C21: =1-0.45 -> 0.55
A22: refinery | B22: =B21+1 -> 21 | C22: =1-0.45 -> 0.55
A23: refinery | B23: =B22+1 -> 22 | C23: 0.8
A24: refinery | B24: =B23+1 -> 23 | C24: 0.8
A25: refinery | B25: =B24+1 -> 24 | C25: 0.8
A26: refinery | B26: =B25+1 -> 25 | C26: 0.8
A27: refinery | B27: =B26+1 -> 26 | C27: 0.8
A28: refinery | B28: =B27+1 -> 27 | C28: 0.8
A29: refinery | B29: =B28+1 -> 28 | C29: 0.8
A30: ports | B30: 1 | C30: 0
A31: ports | B31: 2 | C31: 0
A32: ports | B32: 3 | C32: 0

Sheet pipeline_segments
A1: pipeline_segment | B1: upstream_connection | C1: leadtime | D1: capacity_bbl_day
A2: LA_Interior | C2: 1 | D2: =(terminals!E5+terminals!E6)*1.05 -> 293296.5
A3: LA_Colton | C3: 1 | D3: =(terminals!E7+terminals!E9+terminals!E10+terminals!E2+terminals!E4)*1.05 -> 329021.17
A4: Colton_Imperial | B4: =A3 -> LA_Colton | C4: 3 | D4: =(terminals!E2+terminals!E4)*1.05 -> 129028.73
A5: Imperial_Phoenix | B5: =A4 -> Colton_Imperial | C5: 4 | D5: =terminals!E4*1.05 -> 93118.725
A6: Colton_Barstow | B6: =A3 -> LA_Colton | C6: 2 | D6: =(terminals!E9+terminals!E10)*1.05 -> 95705.4
A7: Barstow_Vegas | B7: =A6 -> Colton_Barstow | C7: 2 | D7: =terminals!E10*1.05 -> 77696.85
A8: LA_Bakersfield | C8: 2 | D8: =terminals!E8*1.05 -> 65807.7
A9: LA_SanDiego | C9: 2 | D9: =terminals!E3*1.05 -> 68917.8

Sheet pipeline_disruption_scenario
A1: pipeline_segment | B1: day | C1: percentage_of_capacity
A2: LA_interior | B2: 1 | C2: 0
A3: LA_interior | B3: 2 | C3: 0
A4: LA_interior | B4: 3 | C4: 0
A5: LA_Colton | B5: 1 | C5: 0
A6: LA_Colton | B6: =B5+1 -> 2 | C6: 0
A7: LA_Colton | B7: =B6+1 -> 3 | C7: 0
A8: LA_Colton | B8: =B7+1 -> 4 | C8: 0
A9: LA_Colton | B9: =B8+1 -> 5 | C9: 0
A10: LA_Colton | B10: =B9+1 -> 6 | C10: 0
A11: LA_Colton | B11: =B10+1 -> 7 | C11: 0
A12: LA_Colton | B12: =B11+1 -> 8 | C12: 0
A13: LA_Colton | B13: =B12+1 -> 9 | C13: 0
A14: LA_Colton | B14: =B13+1 -> 10 | C14: 0
A15: LA_Colton | B15: =B14+1 -> 11 | C15: 0
A16: LA_Colton | B16: =B15+1 -> 12 | C16: 0
A17: LA_Colton | B17: =B16+1 -> 13 | C17: 0
... A25: LA_Colton | B25: =B24+1 -> 21 | C25: 0
A26: Colton_Barstow | B26: 1 | C26: 0
A27: Colton_Barstow | B27: =B26+1 -> 2 | C27: 0
A28: Colton_Barstow | B28: =B27+1 -> 3 | C28: 0
A29: Colton_Barstow | B29: =B28+1 -> 4 | C29: 0
A30: Colton_Barstow | B30: =B29+1 -> 5 | C30: 0
A31: Colton_Barstow | B31: =B30+1 -> 6 | C31: 0
A32: Colton_Barstow | B32: =B31+1 -> 7 | C32: 0
A33: Colton_Barstow | B33: =B32+1 -> 8 | C33: 0
A34: Colton_Barstow | B34: =B33+1 -> 9 | C34: 0
A35: Colton_Barstow | B35: =B34+1 -> 10 | C35: 0
A36: Colton_Barstow | B36: =B35+1 -> 11 | C36: 0
A37: Colton_Barstow | B37: =B36+1 -> 12 | C37: 0
A38: Colton_Barstow | B38: =B37+1 -> 13 | C38: 0
... A67: Colton_Barstow | B67: =B66+1 -> 42 | C67: 0
A68: Colton_Imperial | B68: 1 | C68: 0
A69: Colton_Imperial | B69: =B68+1 -> 2 | C69: 0
A70: Colton_Imperial | B70: =B69+1 -> 3 | C70: 0
A71: Colton_Imperial | B71: =B70+1 -> 4 | C71: 0
A72: Colton_Imperial | B72: =B71+1 -> 5 | C72: 0
A73: Colton_Imperial | B73: =B72+1 -> 6 | C73: 0
A74: Colton_Imperial | B74: =B73+1 -> 7 | C74: 0
A75: Colton_Imperial | B75: =B74+1 -> 8 | C75: 0
...

Sheet terminals
A1: terminal_group | B1: pipeline | C1: initial_inventory_days | D1: target_inventory_on_hand | E1: default_demand_bbl_day
A2: Imperial | B2: Colton_Imperial | C2: 12 | D2: 12 | E2: 34200
A3: San Diego | B3: LA_SanDiego | C3: 12 | D3: 12 | E3: 65636
A4: Phoenix | B4: Imperial_Phoenix | C4: 12 | D4: 12 | E4: =177369/2 -> 88684.5
A5: Los Angeles | B5: LA_Interior | C5: 12 | D5: 12 | E5: 155957
A6: Orange | B6: LA_Interior | C6: 12 | D6: 12 | E6: 123373
A7: Colton | B7: LA_Colton | C7: 12 | D7: 12 | E7: 99321
A8: Bakersfield | B8: LA_Bakersfield | C8: 12 | D8: 12 | E8: 62674
A9: Barstow | B9: Colton_Barstow | C9: 12 | D9: 12 | E9: 17151
A10: Las Vegas | B10: Barstow_Vegas | C10: 12 | D10: 12 | E10: 73997

Sheet pipeline_leadtime_estimation
A1: Segment | B1: Miles (approx) | C1: Fast (120) | D1: Typical (90) | E1: Slow (70)
A2: Los Angeles → Colton | B2: 55 | C2: 0.46 | D2: 0.61 | E2: 0.79 | F2: =ROUND(E2,0) -> 1
A3: Colton → Imperial (Imperial Valley) | B3: 175 | C3: 1.46 | D3: 1.94 | E3: 2.5 | F3: =ROUND(E3,0) -> 3
A4: Imperial → Phoenix | B4: 285 | C4: 2.38 | D4: 3.17 | E4: 4.07 | F4: =ROUND(E4,0) -> 4
A5: Colton → Barstow | B5: 95 | C5: 0.79 | D5: 1.06 | E5: 1.36 | F5: =ROUND(E5,0) -> 1
A6: Barstow → Las Vegas | B6: 155 | C6: 1.29 | D6: 1.72 | E6: 2.21 | F6: =ROUND(E6,0) -> 2
A7: Los Angeles → Bakersfield | B7: 110 | C7: 0.92 | D7: 1.22 | E7: 1.57 | F7: =ROUND(E7,0) -> 2
A8: Los Angeles → San Diego | B8: 120 | C8: 1 | D8: 1.33 | E8: 1.71 | F8: =ROUND(E8,0) -> 2
